Workbook

Sheet kol_master
A1: Name | B1: KOL_ID | C1: Area | D1: Country | E1: Lat | F1: Lon | G1: Location | H1: Notion Link
A2: Dr. Robert Jung | B2: 101001 | C2: Europe | D2: UK | E2: 55.378051 | F2: -3.435973 | G2: Europe - 20
A3: Dr. Filip Rebelo | B3: 102001 | C3: Europe | D3: Sweden
A4: Dr. Alexandre Richard | B4: 103001 | C4: Europe | D4: France | E4: 48.857548 | F4: 2.3513765 | G4: Europe - 20
A5: Dr. Gary Finelle | B5: 103002 | C5: Europe | D5: France | E5: 48.857299 | F5: 2.3011467 | G5: Europe - 20
A6: Dr. Pierre Leclercq | B6: 103003 | C6: Europe | D6: France | E6: 43.403449 | F6: 4.9800614 | G6: Europe - 20
A7: Dr. Emmanuel Bocquet | B7: 103004 | C7: Europe | D7: France | E7: 50.623741 | F7: 3.0395183 | G7: Europe - 20
A8: Dr. Oguz Emeklibas | B8: 104001 | C8: Europe | D8: Germany
A9: Dr. Frank Maier | B9: 104002 | C9: Europe | D9: Germany
A10: Dr. Simon Priess | B10: 104003 | C10: Europe | D10: Germany
A11: Dr. Justinas Pletkus | B11: 105001 | C11: Europe | D11: Lithuania | E11: 55.169438 | F11: 23.881275 | G11: Europe - 20
A12: Dr. Gabriel Musetescu | B12: 106001 | C12: Europe | D12: Romania | E12: 44.426767 | F12: 26.102538 | G12: Europe - 20
A13: Dr. Michalis Diomataris | B13: 107001 | C13: Europe | D13: Greece | E13: 37.982358 | F13: 23.737233 | G13: Europe - 20
A14: Dr. Grzegorz Wasiluk | B14: 108001 | C14: Europe | D14: Poland | E14: 52.229676 | F14: 21.012229 | G14: Europe - 20
A15: Dr. Łukasz Zadrożny | B15: 108003 | C15: Europe | D15: Poland | E15: 52.346917 | F15: 20.899641 | G15: Europe - 20
A16: Dr. Anton Sadovnyshyi | B16: 109001 | C16: Europe | D16: Ukraine
A17: Dr. Yevhenii Sluchevskyi | B17: 109002 | C17: Europe | D17: Ukraine | E17: 50.430371 | F17: 30.47585 | G17: Europe - 20
A18: Dr. Veiko Vengerfeldt | B18: 110001 | C18: Europe | D18: Estonia | E18: 58.372636 | F18: 26.719974 | G18: Europe - 20
A19: Dr. Marco Tallarico | B19: 111001 | C19: Europe | D19: Italy | E19: 41.858696 | F19: 12.440879 | G19: Europe - 20
A20: Dr. Antonino Cacioppo | B20: 111002 | C20: Europe | D20: Italy | E20: 38.130288 | F20: 13.332582 | G20: Europe - 20
A21: Dr. Janghyun Paek | B21: 201001 | C21: APAC | D21: Korea | E21: 37.370175 | F21: 126.6503 | G21: APAC - 9
A22: Dr. Sapaar Bayarmagnai | B22: 202001 | C22: APAC | D22: Mongolia | E22: 47.922051 | F22: 106.9155 | G22: APAC - 9
A23: Dr. Swapnil Pande | B23: 203001 | C23: APAC | D23: India | E23: 19.285637 | F23: 72.869109 | G23: APAC - 9
A24: Dr. Priyam Aditya | B24: 203002 | C24: APAC | D24: India | E24: 28.704059 | F24: 77.10249 | G24: APAC - 9
A25: Dr. Ahmad Al Hassiny | B25: 204001 | C25: APAC | D25: New Zealand
A26: Dr. Manapat Thaveeprungsiporn | B26: 205001 | C26: APAC | D26: Thailand | E26: 13.668794 | F26: 100.63397 | G26: APAC - 9
A27: Dr. Sardor Mirakhmedov | B27: 206001 | C27: APAC | D27: Uzbekistan | E27: 41.332147 | F27: 69.331626 | G27: APAC - 9
A28: Dr. Sameh Shaaban | B28: 301001 | C28: MEA | D28: Egypt | E28: 30.04442 | F28: 31.235712 | G28: MEA - 5
A29: Dr. Amr Elkhadem | B29: 301002 | C29: MEA | D29: Egypt | E29: 30.03629 | F29: 31.475829 | G29: MEA - 5
A30: Dr. Mohamed Elashry | B30: 301003 | C30: MEA | D30: Egypt | E30: 31.200092 | F30: 29.918739 | G30: MEA - 5
A31: Dr. Kenneth Lee
A32: Dr. Derek Mahonny
A33: Dr. Arass Jalal Noori
A34: Dr. Rekar Ismail
A35: Dr. Derek Mahonny
A36: Dr. Ahmad Al-Hassiny | E36: -41.292381 | F36: 174.77875 | G36: APAC - 9

Sheet contract_tasks
A1: Name | B1: KOL_ID | C1: Contract_Start | D1: Contract_End | E1: Task | F1: Times | G1: Target_Count
A2: Dr. Robert Jung | B2: 101001 | C2: 45758 | D2: 46022 | E2: Lecture | F2: per quarter | G2: 4
A3: Dr. Robert Jung | B3: 101001 | C3: 45758 | D3: 46022 | E3: Testimonial | F3: per quarter | G3: 1
A4: Dr. Robert Jung | B4: 101001 | C4: 45758 | D4: 46022 | E4: SNS Posting | F4: per quarter | G4: 1
A5: Dr. Robert Jung | B5: 101001 | C5: 45758 | D5: 46022 | E5: Case Report | F5: per quarter | G5: 1
A6: Dr. Robert Jung | B6: 101001 | C6: 45758 | D6: 46022 | E6: R&D Feedback | F6: per quarter | G6: 1
A7: Dr. Robert Jung | B7: 101001 | C7: 45758 | D7: 46022 | E7: Webinar | F7: per quarter | G7: 1
A8: Dr. Robert Jung | B8: 101001 | C8: 45758 | D8: 46022 | E8: Article | F8: per quarter | G8: 1
A9: Dr. Filip Rebelo | B9: 102001 | C9: 45757 | D9: 46022 | E9: Lecture | F9: per quarter | G9: 4
A10: Dr. Filip Rebelo | B10: 102001 | C10: 45757 | D10: 46022 | E10: Testimonial | F10: per quarter | G10: 1
A11: Dr. Filip Rebelo | B11: 102001 | C11: 45757 | D11: 46022 | E11: SNS Posting | F11: per quarter | G11: 1
A12: Dr. Filip Rebelo | B12: 102001 | C12: 45757 | D12: 46022 | E12: Case Report | F12: per quarter | G12: 1
A13: Dr. Filip Rebelo | B13: 102001 | C13: 45757 | D13: 46022 | E13: R&D Feedback | F13: per quarter | G13: 1
... A36: Dr. Oguz Emeklibas | B36: 104001 | C36: 45839 | D36: 46204 | E36: Article | F36: per year | G36: 1
A37: Dr. Justinas Pletkus | B37: 105001 | E37: Lecture | F37: per year | G37: 4
A38: Dr. Justinas Pletkus | B38: 105001 | E38: Testimonial | F38: per year | G38: 1
A39: Dr. Justinas Pletkus | B39: 105001 | E39: SNS Posting | F39: per year | G39: 1
A40: Dr. Justinas Pletkus | B40: 105001 | E40: Case Report | F40: per year | G40: 1
A41: Dr. Justinas Pletkus | B41: 105001 | E41: R&D Feedback | F41: per year | G41: 1
A42: Dr. Justinas Pletkus | B42: 105001 | E42: Webinar | F42: per year | G42: 1
A43: Dr. Justinas Pletkus | B43: 105001 | E43: Article | F43: per year | G43: 1
A44: Dr. Gabriel Musetescu | B44: 106001 | C44: 45778 | D44: 46022 | E44: Lecture | F44: per year | G44: 4
A45: Dr. Gabriel Musetescu | B45: 106001 | C45: 45778 | D45: 46022 | E45: Testimonial | F45: per year | G45: 1
A46: Dr. Gabriel Musetescu | B46: 106001 | C46: 45778 | D46: 46022 | E46: SNS Posting | F46: per year | G46: 1
A47: Dr. Gabriel Musetescu | B47: 106001 | C47: 45778 | D47: 46022 | E47: Case Report | F47: per year | G47: 1
A48: Dr. Gabriel Musetescu | B48: 106001 | C48: 45778 | D48: 46022 | E48: R&D Feedback | F48: per year | G48: 1
A49: Dr. Gabriel Musetescu | B49: 106001 | C49: 45778 | D49: 46022 | E49: Webinar | F49: per year | G49: 1
A50: Dr. Gabriel Musetescu | B50: 106001 | C50: 45778 | D50: 46022 | E50: Article | F50: per year | G50: 1
A51: Dr. Michalis Diomataris | B51: 107001 | C51: 45839 | D51: 46204 | E51: Lecture | F51: per year | G51: 5
A52: Dr. Michalis Diomataris | B52: 107001 | C52: 45839 | D52: 46204 | E52: Testimonial | F52: per year | G52: 1
A53: Dr. Michalis Diomataris | B53: 107001 | C53: 45839 | D53: 46204 | E53: SNS Posting | F53: per year | G53: 1
A54: Dr. Michalis Diomataris | B54: 107001 | C54: 45839 | D54: 46204 | E54: Case Report | F54: per year | G54: 1
A55: Dr. Michalis Diomataris | B55: 107001 | C55: 45839 | D55: 46204 | E55: R&D Feedback | F55: per year | G55: 1
... A57: Dr. Michalis Diomataris | B57: 107001 | C57: 45839 | D57: 46204 | E57: Article | F57: per year | G57: 1
A58: Dr. Grzegorz Wasiluk | B58: 108001 | E58: Lecture | F58: per year | G58: 4
A59: Dr. Grzegorz Wasiluk | B59: 108001 | E59: Testimonial | F59: per year | G59: 1
A60: Dr. Grzegorz Wasiluk | B60: 108001 | E60: SNS Posting | F60: per year | G60: 1
A61: Dr. Grzegorz Wasiluk | B61: 108001 | E61: Case Report | F61: per year | G61: 1
A62: Dr. Grzegorz Wasiluk | B62: 108001 | E62: R&D Feedback | F62: per year | G62: 1
A63: Dr. Grzegorz Wasiluk | B63: 108001 | E63: Webinar | F63: per year | G63: 1
...

Sheet activity_log
A1: Name | B1: KOL_ID | C1: Date | D1: Contract_End | E1: Task | F1: Activity | G1: Source(Planned/TBD) | H1: Status(Planned/On Progress/Done) | I1: Delayed | J1: Notes
A2: Dr. Alexandre Richard | B2: 103001 | C2: 46020 | D2: =VLOOKUP($B2,contract_tasks!$B$2:$D$148,3,0) -> 46022 | E2: Case Report | F2: case report | G2: TBD | H2: Planned | I2: =IF(H2="Done", "", IF(TODAY() >= EDATE(D2, -1), IF(TODAY() > C2, "Delayed", "Warning"), ""))
A3: Dr. Pierre Leclercq | B3: 103003 | C3: 46020 | D3: 46022 | E3: Case Report | F3: case report | G3: TBD | H3: Planned | I3: =IF(H3="Done", "", IF(TODAY() >= EDATE(D3, -1), IF(TODAY() > C3, "Delayed", "Warning"), ""))
A4: Dr. Emmanuel Bocquet | B4: 103004 | C4: 46020 | D4: =VLOOKUP($B4,contract_tasks!$B$2:$D$148,3,0) -> 46022 | E4: Case Report | F4: case report | G4: TBD | H4: Planned | I4: =IF(H4="Done", "", IF(TODAY() >= EDATE(D4, -1), IF(TODAY() > C4, "Delayed", "Warning"), ""))
A5: Dr. Veiko Vengerfeldt | B5: 110001 | C5: 46020 | D5: 46022 | E5: Case Report | F5: case report | G5: TBD | H5: Planned | I5: =IF(H5="Done", "", IF(TODAY() >= EDATE(D5, -1), IF(TODAY() > C5, "Delayed", "Warning"), ""))
A6: Dr. Sameh Shaaban | B6: 301001 | C6: 46020 | D6: =VLOOKUP($B6,contract_tasks!$B$2:$D$148,3,0) -> 46022 | E6: Case Report | F6: case report | G6: TBD | H6: Planned | I6: =IF(H6="Done", "", IF(TODAY() >= EDATE(D6, -1), IF(TODAY() > C6, "Delayed", "Warning"), ""))
A7: Dr. Derek Mahonny | C7: 46020 | D7: 46022 | E7: Case Report | F7: case report | G7: TBD | H7: Planned | I7: =IF(H7="Done", "", IF(TODAY() >= EDATE(D7, -1), IF(TODAY() > C7, "Delayed", "Warning"), ""))
A8: Dr. Derek Mahonny | C8: 46020 | D8: 46022 | E8: Case Report | F8: case report | G8: TBD | H8: Planned | I8: =IF(H8="Done", "", IF(TODAY() >= EDATE(D8, -1), IF(TODAY() > C8, "Delayed", "Warning"), ""))
A9: Dr. Alexandre Richard | B9: 103001 | C9: 46000 | D9: =VLOOKUP($B9,contract_tasks!$B$2:$D$148,3,0) -> 46022 | E9: Lecture | F9: Lecture | G9: Planned | H9: Planned | I9: =IF(H9="Done", "", IF(TODAY() >= EDATE(D9, -1), IF(TODAY() > C9, "Delayed", "Warning"), ""))
A10: Dr. Alexandre Richard | B10: 103001 | C10: 45990 | D10: =VLOOKUP($B10,contract_tasks!$B$2:$D$148,3,0) -> 46022 | E10: Lecture | F10: Lecture | G10: TBD | H10: On Progress | I10: =IF(H10="Done", "", IF(TODAY() >= EDATE(D10, -1), IF(TODAY() > C10, "Delayed", "Warning"), ""))
A11: Dr. Gary Finelle | B11: 103002 | C11: 45990 | D11: 45991 | E11: Lecture | F11: Lecture | G11: TBD | H11: On Progress | I11: =IF(H11="Done", "", IF(TODAY() >= EDATE(D11, -1), IF(TODAY() > C11, "Delayed", "Warning"), "")) -> Warning
A12: Dr. Pierre Leclercq | B12: 103003 | C12: 45990 | D12: 45991 | E12: Lecture | F12: Lecture | G12: TBD | H12: On Progress | I12: =IF(H12="Done", "", IF(TODAY() >= EDATE(D12, -1), IF(TODAY() > C12, "Delayed", "Warning"), "")) -> Warning
A13: Dr. Emmanuel Bocquet | B13: 103004 | C13: 45990 | D13: =VLOOKUP($B13,contract_tasks!$B$2:$D$148,3,0) -> 46022 | E13: Lecture | F13: Lecture | G13: TBD | H13: On Progress | I13: =IF(H13="Done", "", IF(TODAY() >= EDATE(D13, -1), IF(TODAY() > C13, "Delayed", "Warning"), ""))
A14: Dr. Oguz Emeklibas | B14: 104001 | C14: 45983 | D14: =VLOOKUP($B14,contract_tasks!$B$2:$D$148,3,0) -> 46204 | E14: Lecture | F14: Lecture | G14: TBD | H14: On Progress | I14: =IF(H14="Done", "", IF(TODAY() >= EDATE(D14, -1), IF(TODAY() > C14, "Delayed", "Warning"), ""))
A15: Dr. Łukasz Zadrożny | B15: 108003 | C15: 45983 | D15: =VLOOKUP($B15,contract_tasks!$B$2:$D$148,3,0) -> 46022 | E15: Lecture | F15: Lecture | G15: TBD | H15: On Progress | I15: =IF(H15="Done", "", IF(TODAY() >= EDATE(D15, -1), IF(TODAY() > C15, "Delayed", "Warning"), ""))
A16: Dr. Ahmad Al Hassiny | B16: 204001 | C16: 45976 | D16: =VLOOKUP($B16,contract_tasks!$B$2:$D$148,3,0) -> 46231 | E16: SNS Posting | F16: ContentsCreation | G16: TBD | H16: On Progress | I16: =IF(H16="Done", "", IF(TODAY() >= EDATE(D16, -1), IF(TODAY() > C16, "Delayed", "Warning"), ""))
A17: Dr. Emmanuel Bocquet | B17: 103004 | C17: 45975 | D17: =VLOOKUP($B17,contract_tasks!$B$2:$D$148,3,0) -> 46022 | E17: Lecture | F17: Lecture | G17: Planned | H17: Planned | I17: =IF(H17="Done", "", IF(TODAY() >= EDATE(D17, -1), IF(TODAY() > C17, "Delayed", "Warning"), "")) | J17: ADF 2025
A18: Dr. Emmanuel Bocquet | B18: 103004 | C18: 45962 | D18: =VLOOKUP($B18,contract_tasks!$B$2:$D$148,3,0) -> 46022 | E18: Lecture | F18: Lecture | G18: Planned | H18: Planned | I18: =IF(H18="Done", "", IF(TODAY() >= EDATE(D18, -1), IF(TODAY() > C18, "Delayed", "Warning"), ""))
A19: Dr. Ahmad Al Hassiny | B19: 204001 | C19: 45962 | D19: =VLOOKUP($B19,contract_tasks!$B$2:$D$148,3,0) -> 46231 | E19: SNS Posting | F19: ContentsCreation | G19: TBD | H19: On Progress | I19: =IF(H19="Done", "", IF(TODAY() >= EDATE(D19, -1), IF(TODAY() > C19, "Delayed", "Warning"), ""))
A20: Dr. Antonino Cacioppo | B20: 111002 | C20: 45959 | D20: 45991 | E20: SNS Posting | F20: ContentsCreation | G20: TBD | H20: On Progress | I20: =IF(H20="Done", "", IF(TODAY() >= EDATE(D20, -1), IF(TODAY() > C20, "Delayed", "Warning"), "")) -> Delayed
A21: Dr. Oguz Emeklibas | B21: 104001 | C21: 45955 | D21: =VLOOKUP($B21,contract_tasks!$B$2:$D$148,3,0) -> 46204 | E21: Lecture | F21: Lecture | G21: Planned | H21: Planned | I21: =IF(H21="Done", "", IF(TODAY() >= EDATE(D21, -1), IF(TODAY() > C21, "Delayed", "Warning"), "")) | J21: Vanest Launching Show
A22: Dr. Robert Jung | B22: 101001 | C22: 45952 | D22: =VLOOKUP($B22,contract_tasks!$B$2:$D$148,3,0) -> 46022 | E22: Lecture | F22: Lecture | G22: TBD | H22: Done | I22: =IF(H22="Done", "", IF(TODAY() >= EDATE(D22, -1), IF(TODAY() > C22, "Delayed", "Warning"), ""))
A23: Dr. Oguz Emeklibas | B23: 104001 | C23: 45952 | D23: =VLOOKUP($B23,contract_tasks!$B$2:$D$148,3,0) -> 46204 | E23: Lecture | F23: Lecture | G23: TBD | H23: Done | I23: =IF(H23="Done", "", IF(TODAY() >= EDATE(D23, -1), IF(TODAY() > C23, "Delayed", "Warning"), ""))
A24: Dr. Simon Priess | B24: 104003 | C24: 45952 | D24: 45991 | E24: SNS Posting | F24: ContentsCreation | G24: TBD | H24: On Progress | I24: =IF(H24="Done", "", IF(TODAY() >= EDATE(D24, -1), IF(TODAY() > C24, "Delayed", "Warning"), "")) -> Delayed
A25: Dr. Ahmad Al Hassiny | B25: 204001 | C25: 45952 | D25: =VLOOKUP($B25,contract_tasks!$B$2:$D$148,3,0) -> 46231 | E25: SNS Posting | F25: ContentsCreation | G25: TBD | H25: Done | I25: =IF(H25="Done", "", IF(TODAY() >= EDATE(D25, -1), IF(TODAY() > C25, "Delayed", "Warning"), ""))
A26: Dr. Amr Elkhadem | B26: 301002 | C26: 45952 | D26: =VLOOKUP($B26,contract_tasks!$B$2:$D$148,3,0) -> 46022 | E26: Lecture | F26: Lecture | G26: TBD | H26: Done | I26: =IF(H26="Done", "", IF(TODAY() >= EDATE(D26, -1), IF(TODAY() > C26, "Delayed", "Warning"), ""))
A27: Dr. Grzegorz Wasiluk | B27: 108001 | C27: 45949 | D27: 45991 | E27: Testimonial | F27: Testimonial | G27: Planned | H27: Planned | I27: =IF(H27="Done", "", IF(TODAY() >= EDATE(D27, -1), IF(TODAY() > C27, "Delayed", "Warning"), "")) -> Delayed
A28: Dr. Sameh Shaaban | B28: 301001 | C28: 45949 | D28: =VLOOKUP($B28,contract_tasks!$B$2:$D$148,3,0) -> 46022 | E28: Testimonial | F28: Testimonial | G28: Planned | H28: Planned | I28: =IF(H28="Done", "", IF(TODAY() >= EDATE(D28, -1), IF(TODAY() > C28, "Delayed", "Warning"), ""))
A29: Dr. Łukasz Zadrożny | B29: 108003 | C29: 45945 | D29: =VLOOKUP($B29,contract_tasks!$B$2:$D$148,3,0) -> 46022 | E29: Lecture | F29: Lecture | G29: TBD | H29: Done | I29: =IF(H29="Done", "", IF(TODAY() >= EDATE(D29, -1), IF(TODAY() > C29, "Delayed", "Warning"), ""))
A30: Dr. Sapaar Bayarmagnai | B30: 202001 | C30: 45945 | D30: =VLOOKUP($B30,contract_tasks!$B$2:$D$148,3,0) -> 46022 | E30: Lecture | F30: Lecture | G30: TBD | H30: Done | I30: =IF(H30="Done", "", IF(TODAY() >= EDATE(D30, -1), IF(TODAY() > C30, "Delayed", "Warning"), ""))
A31: Dr. Amr Elkhadem | B31: 301002 | C31: 45945 | D31: =VLOOKUP($B31,contract_tasks!$B$2:$D$148,3,0) -> 46022 | E31: Article | F31: Clinical Paper | G31: TBD | H31: Done | I31: =IF(H31="Done", "", IF(TODAY() >= EDATE(D31, -1), IF(TODAY() > C31, "Delayed", "Warning"), ""))
A32: Dr. Anton Sadovnyshyi | B32: 109001 | C32: 45938 | D32: =VLOOKUP($B32,contract_tasks!$B$2:$D$148,3,0) -> 46216 | E32: Lecture | F32: Lecture | G32: TBD | H32: Done | I32: =IF(H32="Done", "", IF(TODAY() >= EDATE(D32, -1), IF(TODAY() > C32, "Delayed", "Warning"), ""))
A33: Dr. Yevhenii Sluchevskyi | B33: 109002 | C33: 45938 | D33: =VLOOKUP($B33,contract_tasks!$B$2:$D$148,3,0) -> 46216 | E33: Lecture | F33: Lecture | G33: TBD | H33: Done | I33: =IF(H33="Done", "", IF(TODAY() >= EDATE(D33, -1), IF(TODAY() > C33, "Delayed", "Warning"), ""))
A34: Dr. Veiko Vengerfeldt | B34: 110001 | C34: 45938 | D34: 45991 | E34: Lecture | F34: Lecture | G34: TBD | H34: On Progress | I34: =IF(H34="Done", "", IF(TODAY() >= EDATE(D34, -1), IF(TODAY() > C34, "Delayed", "Warning"), "")) -> Delayed
A35: Dr. Marco Tallarico | B35: 111001 | C35: 45938 | D35: =VLOOKUP($B35,contract_tasks!$B$2:$D$148,3,0) -> 46088 | E35: Lecture | F35: Lecture | G35: TBD | H35: Done | I35: =IF(H35="Done", "", IF(TODAY() >= EDATE(D35, -1), IF(TODAY() > C35, "Delayed", "Warning"), ""))
A36: Dr. Ahmad Al Hassiny | B36: 204001 | C36: 45938 | D36: =VLOOKUP($B36,contract_tasks!$B$2:$D$148,3,0) -> 46231 | E36: SNS Posting | F36: ContentsCreation | G36: TBD | H36: Done | I36: =IF(H36="Done", "", IF(TODAY() >= EDATE(D36, -1), IF(TODAY() > C36, "Delayed", "Warning"), ""))
A37: Dr. Sardor Mirakhmedov | B37: 206001 | C37: 45938 | D37: =VLOOKUP($B37,contract_tasks!$B$2:$D$148,3,0) -> 46247 | E37: SNS Posting | F37: ContentsCreation | G37: TBD | H37: Done | I37: =IF(H37="Done", "", IF(TODAY() >= EDATE(D37, -1), IF(TODAY() > C37, "Delayed", "Warning"), ""))
A38: Dr. Justinas Pletkus | B38: 105001 | C38: 45931 | D38: 45991 | E38: Other | G38: Planned | H38: Planned | I38: =IF(H38="Done", "", IF(TODAY() >= EDATE(D38, -1), IF(TODAY() > C38, "Delayed", "Warning"), "")) -> Delayed
A39: Dr. Łukasz Zadrożny | B39: 108003 | C39: 45931 | D39: =VLOOKUP($B39,contract_tasks!$B$2:$D$148,3,0) -> 46022 | E39: Other | G39: Planned | H39: Planned | I39: =IF(H39="Done", "", IF(TODAY() >= EDATE(D39, -1), IF(TODAY() > C39, "Delayed", "Warning"), ""))
A40: Dr. Anton Sadovnyshyi | B40: 109001 | C40: 45931 | D40: =VLOOKUP($B40,contract_tasks!$B$2:$D$148,3,0) -> 46216 | E40: R&D Feedback | F40: i900MTest | G40: TBD | H40: Done | I40: =IF(H40="Done", "", IF(TODAY() >= EDATE(D40, -1), IF(TODAY() > C40, "Delayed", "Warning"), ""))
...
